Workbook

Sheet Instructions
A1: ITC327W Project Progress and Contribution Workbook
A3: Use this workbook throughout the semester. Update it after each project phase and submit the same workbook again so that progress can be tracked over time.
A5: Sheet | B5: Purpose | D5: Evidence and Accountability Rules
A6: Project Overview | B6: Enter the group and project details. The dashboard summarises task progress automatically. | D6: 1 | E6: Every student must be assigned meaningful work in Microsoft Project.
A7: Task Progress | B7: Record planned and completed tasks, responsible students, dates, status, percentage completed and evidence. | D7: 2 | E7: Completed work must be supported by evidence such as GitHub activity, meeting records, document sections, screenshots or stakeholder communication.
A8: Individual Contributions | B8: Record the work personally completed by each student. Every entry must have evidence. | D8: 3 | E8: GitHub commits are not the only evidence. Planning, interviewing, documentation, coordination and quality review also count.
A9: Stakeholder Engagement | B9: Record meetings, calls and emails with the stakeholder and the main outcomes. | D9: 4 | E9: Do not record work as completed by a student when it was completed by someone else.
A10: Challenges & Actions | B10: Record project challenges, their effect and the corrective action taken. | D10: 5 | E10: Do not place passwords, API keys, identity numbers, private contact details or confidential records in this workbook or on GitHub.
A11: Phase Summary | B11: Provide a short summary of the phase, including achievements, outstanding work and participation concerns. | D11: 6 | E11: The confidential individual peer evaluation must be completed separately on Blackboard.
A12: Group Reflection | B12: Complete one shared reflection after each phase. Be honest and specific.
D13: Recommended Update Points
D14: Unit 1 / Phase 1 | E14: Planning, stakeholder engagement, requirements and initial SRS
D15: Phase 2 | E15: Architecture, UML, ERD and interface design
D16: Phase 3 | E16: Development, integration, testing and demonstration
D17: Final | E17: Overall project summary and final reflection

Sheet Project Overview
A1: Project Overview and Progress Dashboard
A3: Project Information | B3: Group Response | F3: Task Status | G3: Count
A4: Group name or number | B4: Bright Web Crafters | F4: Completed | G4: =COUNTIF('Task Progress'!H2:H101,"Completed") -> 30
A5: Project title | B5: School Portal System (School-Parental System) - ITC327W | F5: In Progress | G5: 0
A6: Stakeholder or organisation | B6: Reitzpark Primary School, Lenakeng High school, Thabong primary school | F6: Not Started | G6: =COUNTIF('Task Progress'!H2:H101,"Not Started") -> 0
A7: Group mentor | F7: Delayed | G7: =COUNTIF('Task Progress'!H2:H101,"Delayed") -> 0
A8: Reporting phase | B8: Final | F8: Blocked | G8: =COUNTIF('Task Progress'!H2:H101,"Blocked") -> 0
A9: Reporting period | F9: Overdue | G9: =COUNTIF('Task Progress'!M2:M101,"Overdue") -> 0
A10: Overall status | B10: Completed
A11: Overall % complete | B11: 1 | F11: Contribution Summary | G11: Count
A12: Main achievement | B12: Build our fully functional School Prental System | F12: Contribution entries | G12: =COUNTIF('Individual Contributions'!E3:E201,"?*") -> 12
A13: Main challenge | B13: Being able to link our ASP.NET with supabase and flutter so that whatever that is upload on our ASP.NET application must appear on our flutter app e.g such as attendance that is marked on our ASP.NET must be visible on the flutter app | F13: Verified entries | G13: =COUNTIFS('Individual Contributions'!E3:E201,"?*",'Individual Contributions'!J3:J201,"Yes") -> 12
A14: Next planned activity | B14: None | F14: Unverified entries | G14: =COUNTIFS('Individual Contributions'!E3:E201,"?*",'Individual Contributions'!J3:J201,"No") -> 0
F15: Stakeholder engagements | G15: 2

Sheet Task Progress
A1: Task Progress Tracker
A2: Task ID | B2: Reporting Phase | C2: Activity | D2: Task Description | E2: Assigned Student(s) | F2: Start Date | G2: Due Date | H2: Status | I2: % Complete | J2: Evidence / Link | K2: Verified by Group | L2: Lecturer Comment | M2: Progress Flag
A3: U1-01 | B3: Unit 1 / Phase 1 | C3: Activity 1.1 | D3: Identify and confirm the external stakeholder | E3: Group | H3: Completed | I3: 100 | J3: Stakeholder interview forms signed by Reitzpark Primary School staff | K3: Yes | M3: =IF(D3="","",IF(H3="Completed","Completed",IF(H3="Blocked","Blocked",IF(H3="Delayed","Delayed",IF(AND(G3<>"",G3<TODAY(),H3<>"Completed"),"Overdue","On Track"))))) -> Completed
A4: U1-02 | B4: Unit 1 / Phase 1 | C4: Activity 1.1 | D4: Document the current process and problem | E4: Group | H4: Completed | I4: 100 | J4: Problem Statement (SRS Sec. 1) and Current Process diagram (SRS Sec. 2.5.1) | K4: Yes | M4: =IF(D4="","",IF(H4="Completed","Completed",IF(H4="Blocked","Blocked",IF(H4="Delayed","Delayed",IF(AND(G4<>"",G4<TODAY(),H4<>"Completed"),"Overdue","On Track"))))) -> Completed
A5: U1-03 | B5: Unit 1 / Phase 1 | C5: Activity 1.1 | D5: Define the project aim, objectives and scope | E5: Group | H5: Completed | I5: 100 | J5: SRS Sections 2.2-2.4 (Scope, Project Aim, Project Objectives) | K5: Yes | M5: =IF(D5="","",IF(H5="Completed","Completed",IF(H5="Blocked","Blocked",IF(H5="Delayed","Delayed",IF(AND(G5<>"",G5<TODAY(),H5<>"Completed"),"Overdue","On Track"))))) -> Completed
A6: U1-04 | B6: Unit 1 / Phase 1 | C6: Activity 1.2 | D6: Prepare stakeholder interview questions | E6: Group | H6: Completed | I6: 100 | J6: Interview questionnaire used with Reitzpark Primary School staff | K6: Yes | M6: =IF(D6="","",IF(H6="Completed","Completed",IF(H6="Blocked","Blocked",IF(H6="Delayed","Delayed",IF(AND(G6<>"",G6<TODAY(),H6<>"Completed"),"Overdue","On Track"))))) -> Completed
A7: U1-05 | B7: Unit 1 / Phase 1 | C7: Activity 1.2 | D7: Conduct and document the stakeholder interview | E7: Group | H7: Completed | I7: 100 | J7: 3 completed, signed interview forms from Reitzpark Primary School (Administrator, Educator, Remedial Education), school-stamped | K7: Yes | M7: =IF(D7="","",IF(H7="Completed","Completed",IF(H7="Blocked","Blocked",IF(H7="Delayed","Delayed",IF(AND(G7<>"",G7<TODAY(),H7<>"Completed"),"Overdue","On Track"))))) -> Completed
A8: U1-06 | B8: Unit 1 / Phase 1 | C8: Activity 1.3 | D8: Compile the initial SRS | E8: Group | H8: Completed | I8: 100 | J8: BRIGHT_WEB_CRAFTERS_SRS.pdf (full SRS document, Sections 1-13) | K8: Yes | M8: =IF(D8="","",IF(H8="Completed","Completed",IF(H8="Blocked","Blocked",IF(H8="Delayed","Delayed",IF(AND(G8<>"",G8<TODAY(),H8<>"Completed"),"Overdue","On Track"))))) -> Completed
A9: U1-07 | B9: Unit 1 / Phase 1 | C9: Activity 1.3 | D9: Create the initial Microsoft Project schedule | E9: Group | H9: Completed | I9: 100 | J9: Attached screenshots to our srs submission | K9: Yes | M9: =IF(D9="","",IF(H9="Completed","Completed",IF(H9="Blocked","Blocked",IF(H9="Delayed","Delayed",IF(AND(G9<>"",G9<TODAY(),H9<>"Completed"),"Overdue","On Track"))))) -> Completed
A10: U1-08 | B10: Unit 1 / Phase 1 | C10: Activity 1.3 | D10: Create and configure the GitHub repository | E10: Group | H10: Completed | I10: 100 | K10: Yes | M10: =IF(D10="","",IF(H10="Completed","Completed",IF(H10="Blocked","Blocked",IF(H10="Delayed","Delayed",IF(AND(G10<>"",G10<TODAY(),H10<>"Completed"),"Overdue","On Track"))))) -> Completed
A11: U1-09 | B11: Unit 1 / Phase 1 | C11: Activity 1.3 | D11: Create the initial Supabase project | E11: Group | H11: Completed | I11: 100 | K11: Yes | M11: =IF(D11="","",IF(H11="Completed","Completed",IF(H11="Blocked","Blocked",IF(H11="Delayed","Delayed",IF(AND(G11<>"",G11<TODAY(),H11<>"Completed"),"Overdue","On Track"))))) -> Completed
A12: U1-10 | B12: Unit 1 / Phase 1 | C12: Activity 1.3 | D12: Complete the progress report and contribution record | E12: Group | H12: Completed | I12: 100 | J12: ITC327W_Project_Progress_Tracker_2026.xlsx (this workbook, being updated) | K12: Yes | M12: =IF(D12="","",IF(H12="Completed","Completed",IF(H12="Blocked","Blocked",IF(H12="Delayed","Delayed",IF(AND(G12<>"",G12<TODAY(),H12<>"Completed"),"Overdue","On Track"))))) -> Completed
A13: U1-11 | B13: Unit 1 / Phase 1 | C13: Activity 1.3 | D13: Complete the Unit 1 group reflection | E13: Group | H13: Completed | I13: 100 | K13: Yes | M13: =IF(D13="","",IF(H13="Completed","Completed",IF(H13="Blocked","Blocked",IF(H13="Delayed","Delayed",IF(AND(G13<>"",G13<TODAY(),H13<>"Completed"),"Overdue","On Track"))))) -> Completed
A14: U1-12 | B14: Unit 1 / Phase 1 | C14: Activity 2.1 | D14: Evaluate technical, operational, economic, schedule and legal/ethical feasibility of the proposed project | E14: Group | H14: In Progress | I14: 100 | J14: SRS Sections 2.2.3 (Exclusions), 2.2.4 (Constraints) and 2.2.5 (Assumptions) already document scope, technical and schedule limits; formal feasibility study (technical/operational/economic/schedule/legal-ethical) still to be written up | K14: Yes | M14: =IF(D14="","",IF(H14="Completed","Completed",IF(H14="Blocked","Blocked",IF(H14="Delayed","Delayed",IF(AND(G14<>"",G14<TODAY(),H14<>"Completed"),"Overdue","On Track"))))) -> On Track
A15: U1-13 | B15: Unit 1 / Phase 1 | C15: Activity 2.2 | D15: Identify, assess (likelihood and impact) and prioritise project risks; prepare a project risk register | E15: Group | H15: Completed | I15: 100 | J15: SRS Section 10 (Risk Analysis) identifies 6 risks - data breach/unauthorised access, multi-school data leakage, incorrect role enforcement, integration failures, network dependency, browser/device compatibility - each with mitigation and contingency plans; likelihood/impact ratings and formal risk register format still to be added | K15: Yes | M15: =IF(D15="","",IF(H15="Completed","Completed",IF(H15="Blocked","Blocked",IF(H15="Delayed","Delayed",IF(AND(G15<>"",G15<TODAY(),H15<>"Completed"),"Overdue","On Track"))))) -> Completed
A16: U1-14 | B16: Unit 1 / Phase 1 | C16: Activity 2.3 | D16: Apply feasibility study and risk register findings: refine project scope, SRS requirements and update the Microsoft Project schedule | E16: Group | H16: Completed | I16: 100 | K16: Yes | M16: =IF(D16="","",IF(H16="Completed","Completed",IF(H16="Blocked","Blocked",IF(H16="Delayed","Delayed",IF(AND(G16<>"",G16<TODAY(),H16<>"Completed"),"Overdue","On Track"))))) -> Completed
A17: U2-01 | B17: Phase 2 | C17: Activity 3.1 | D17: Design the overall system architecture showing how the Flutter mobile app, ASP.NET Core Web API and Supabase backend work together as one integrated solution | E17: Group | H17: Completed | I17: 100 | J17: SRS Section 3.3 (System Environment) already defines the integration points - ASP.NET Core 8 Web API, Flutter mobile app, Supabase PostgreSQL/Auth/Storage; formal system architecture diagram still to be produced | K17: Yes | M17: =IF(D17="","",IF(H17="Completed","Completed",IF(H17="Blocked","Blocked",IF(H17="Delayed","Delayed",IF(AND(G17<>"",G17<TODAY(),H17<>"Completed"),"Overdue","On Track"))))) -> Completed
A18: U2-02 | B18: Phase 2 | C18: Activity 3.2 | D18: Develop the use case diagram, sequence diagrams for key processes, and the Entity Relationship Diagram (ERD) with tables, fields, primary keys and relationships | E18: Group | H18: Completed | I18: 100 | J18: SRS Section 8 (Data Requirements) lists the 12 data entities, fields and relationships (Schools, Users, Students, Teachers, Classes, Enrollments, Attendance, Grades, Announcements, Announcement Recipients, Notifications, Events) as the basis for the ERD; use case diagram, sequence diagrams and the ERD itself still to be developed | K18: Yes | M18: =IF(D18="","",IF(H18="Completed","Completed",IF(H18="Blocked","Blocked",IF(H18="Delayed","Delayed",IF(AND(G18<>"",G18<TODAY(),H18<>"Completed"),"Overdue","On Track"))))) -> Completed
A19: U2-03 | B19: Phase 2 | C19: Activity 3.3 | D19: Design the main Flutter mobile application and ASP.NET web application interfaces and assemble the complete system design baseline | E19: Group | H19: Completed | I19: 100 | J19: https://www.figma.com/proto/pG7mL3Oj2Rr37JAT9r7WJv/School-Parental-system?node-id=42-238&p=f&t=0WVSbhhXYOH6dG98-1&scaling=scale-down&content-scaling=fixed&page-id=0%3A1&starting-point-node-id=42%3A238, https://www.figma.com/proto/lPObV3qt8TfARP7lGBJZqU/School-Parental-System?node-id=197-2563&p=f&viewport=-167%2C288%2C0.1&t=Gi9OyypmECYmlsAf-1&scaling=contain&content-scaling=fixed&starting-point-node-id=197%3A2563&page-id=0%3A1, https://www.figma.com/proto/lPObV3qt8TfARP7lGBJZqU/School-Parental-System?node-id=224-463&p=f&viewport=-107%2C84%2C0.19&t=7iRvLo52rvJGZx2o-1&scaling=contain&content-scaling=fixed&page-id=218%3A2&starting-point-node-id=281%3A2266 | K19: Yes | M19: =IF(D19="","",IF(H19="Completed","Completed",IF(H19="Blocked","Blocked",IF(H19="Delayed","Delayed",IF(AND(G19<>"",G19<TODAY(),H19<>"Completed"),"Overdue","On Track"))))) -> Completed
A20: U3-01 | B20: Phase 3 | C20: Section 1 | D20: Implement the shared Supabase backend from the approved ERD: required tables and fields (Schools, Users, Students, Teachers, Classes, Enrollments, Attendance, Grades, Announcements, Announcement Recipients, Notifications, Events) with primary keys, foreign keys and relationships | E20: Group | H20: Completed | I20: 100 | J20: Supabase project tables and schema script (GitHub backend setup folder); schema screenshots in SRS Implementation section | M20: =IF(D20="","",IF(H20="Completed","Completed",IF(H20="Blocked","Blocked",IF(H20="Delayed","Delayed",IF(AND(G20<>"",G20<TODAY(),H20<>"Completed"),"Overdue","On Track"))))) -> Completed
A21: U3-02 | B21: Phase 3 | C21: Section 1 | D21: Configure Supabase authentication, user roles and permissions (row-level access) as required by the approved SRS, and confirm Flutter and ASP.NET use the same Supabase project with demonstration data | E21: Group | H21: Completed | I21: 100 | J21: Supabase Auth/policy configuration screenshots (no keys shown); dummy demo records | M21: =IF(D21="","",IF(H21="Completed","Completed",IF(H21="Blocked","Blocked",IF(H21="Delayed","Delayed",IF(AND(G21<>"",G21<TODAY(),H21<>"Completed"),"Overdue","On Track"))))) -> Completed
A22: U3-03 | B22: Phase 3 | C22: Section 2 | D22: Develop the Flutter mobile application: main approved screens, navigation, forms and input validation based on the Figma mobile design | E22: Group | H22: Completed | I22: 100 | J22: Source code in mobile/ folder on GitHub; mobile screenshots in SRS | M22: =IF(D22="","",IF(H22="Completed","Completed",IF(H22="Blocked","Blocked",IF(H22="Delayed","Delayed",IF(AND(G22<>"",G22<TODAY(),H22<>"Completed"),"Overdue","On Track"))))) -> Completed
A23: U3-04 | B23: Phase 3 | C23: Section 2 | D23: Connect the Flutter application to Supabase: authentication, role-based access and the main required functions (e.g. attendance, announcements, notifications) | E23: Group | H23: Completed | I23: 100 | J23: Flutter app running against shared Supabase backend; mobile/ folder commits | M23: =IF(D23="","",IF(H23="Completed","Completed",IF(H23="Blocked","Blocked",IF(H23="Delayed","Delayed",IF(AND(G23<>"",G23<TODAY(),H23<>"Completed"),"Overdue","On Track"))))) -> Completed
A24: U3-05 | B24: Phase 3 | C24: Section 3 | D24: Develop the ASP.NET web application: main approved pages, navigation, forms and input validation based on the Figma web design | E24: Group | H24: Completed | I24: 100 | J24: Source code in web/ folder on GitHub; web screenshots in SRS | M24: =IF(D24="","",IF(H24="Completed","Completed",IF(H24="Blocked","Blocked",IF(H24="Delayed","Delayed",IF(AND(G24<>"",G24<TODAY(),H24<>"Completed"),"Overdue","On Track"))))) -> Completed
A25: U3-06 | B25: Phase 3 | C25: Section 3 | D25: Connect the ASP.NET application to Supabase: authentication, role-based access and the main required functions (e.g. marking attendance, posting announcements) | E25: Group | H25: Completed | I25: 100 | J25: ASP.NET app running against the same Supabase backend; web/ folder commits | M25: =IF(D25="","",IF(H25="Completed","Completed",IF(H25="Blocked","Blocked",IF(H25="Delayed","Delayed",IF(AND(G25<>"",G25<TODAY(),H25<>"Completed"),"Overdue","On Track"))))) -> Completed
A26: U3-07 | B26: Phase 3 | C26: Section 4 | D26: Shared process 1 - data submission and retrieval: attendance marked on the ASP.NET web application is saved to Supabase and retrieved on the Flutter mobile application | E26: Group | H26: Completed | I26: 100 | J26: Demonstrated web-to-mobile attendance flow; before/after screenshots in SRS | M26: =IF(D26="","",IF(H26="Completed","Completed",IF(H26="Blocked","Blocked",IF(H26="Delayed","Delayed",IF(AND(G26<>"",G26<TODAY(),H26<>"Completed"),"Overdue","On Track"))))) -> Completed
A27: U3-08 | B27: Phase 3 | C27: Section 4 | D27: Shared process 2 - shared update and display: an authorised update in one application (e.g. announcement or other approved record) is retrieved and displayed in the other application | E27: Group | H27: Completed | I27: 100 | J27: Demonstrated second shared process; screenshots in SRS | M27: =IF(D27="","",IF(H27="Completed","Completed",IF(H27="Blocked","Blocked",IF(H27="Delayed","Delayed",IF(AND(G27<>"",G27<TODAY(),H27<>"Completed"),"Overdue","On Track"))))) -> Completed
A28: U3-09 | B28: Phase 3 | C28: Section 5 | D28: Update the final SRS (single PDF): add Implementation and Final Prototype section with component overview, requirements-to-function table (working/incomplete), screenshots, approved changes, limitations, GitHub link and final Microsoft Project screenshot | E28: Group | H28: Completed | I28: 100 | J28: Updated BRIGHT_WEB_CRAFTERS_SRS.pdf (Phase 3 section in progress) | M28: =IF(D28="","",IF(H28="Completed","Completed",IF(H28="Blocked","Blocked",IF(H28="Delayed","Delayed",IF(AND(G28<>"",G28<TODAY(),H28<>"Completed"),"Overdue","On Track"))))) -> Completed
A29: U3-10 | B29: Phase 3 | C29: Section 6 | D29: Organise GitHub repository (mobile/ and web/ folders, README with setup/run instructions, backend schema scripts) and prepare final source-code ZIP matching the demonstrated version; confirm no passwords or secret keys are included | E29: Group | H29: Completed | I29: 100 | J29: GitHub repository link; ZIP 'Group [Letter] Phase 3' | M29: =IF(D29="","",IF(H29="Completed","Completed",IF(H29="Blocked","Blocked",IF(H29="Delayed","Delayed",IF(AND(G29<>"",G29<TODAY(),H29<>"Completed"),"Overdue","On Track"))))) -> Completed
A30: U3-11 | B30: Phase 3 | C30: Section 6 | D30: Update the Microsoft Project file with actual progress, responsibilities, completed development work and remaining tasks; capture final schedule screenshot for the SRS | E30: Group | H30: Completed | I30: 100 | J30: Updated editable .mpp file; schedule screenshot in SRS | M30: =IF(D30="","",IF(H30="Completed","Completed",IF(H30="Blocked","Blocked",IF(H30="Delayed","Delayed",IF(AND(G30<>"",G30<TODAY(),H30<>"Completed"),"Overdue","On Track"))))) -> Completed
A31: U3-12 | B31: Phase 3 | C31: Section 6 | D31: Update the ITC327W Project Progress Tracker: Task Progress, Individual Contributions, Challenges & Actions, Phase Summary and Phase 3 Group Reflection | E31: Group | H31: Completed | I31: 100 | J31: ITC327W_Project_Progress_Tracker_2026.xlsx (this workbook) | M31: =IF(D31="","",IF(H31="Completed","Completed",IF(H31="Blocked","Blocked",IF(H31="Delayed","Delayed",IF(AND(G31<>"",G31<TODAY(),H31<>"Completed"),"Overdue","On Track"))))) -> Completed
A32: U3-13 | B32: Phase 3 | C32: Section 7 | D32: Prepare the final presentation and live demonstration: stakeholder problem and solution, Supabase backend, mobile demo, web demo, two shared processes, limitations; all members rehearsed for questions | E32: Group | H32: Completed | I32: 100 | J32: Presentation slides and demo script; dummy data prepared | M32: =IF(D32="","",IF(H32="Completed","Completed",IF(H32="Blocked","Blocked",IF(H32="Delayed","Delayed",IF(AND(G32<>"",G32<TODAY(),H32<>"Completed"),"Overdue","On Track"))))) -> Completed
A33: U3-14 | B33: Phase 3 | C33: Section 8 | D33: Submit the group ZIP on Blackboard (one member), and each member completes the confidential individual contribution check | E33: Group | H33: Completed | I33: 100 | M33: =IF(D33="","",IF(H33="Completed","Completed",IF(H33="Blocked","Blocked",IF(H33="Delayed","Delayed",IF(AND(G33<>"",G33<TODAY(),H33<>"Completed"),"Overdue","On Track"))))) -> Completed
M34: =IF(D34="","",IF(H34="Completed","Completed",IF(H34="Blocked","Blocked",IF(H34="Delayed","Delayed",IF(AND(G34<>"",G34<TODAY(),H34<>"Completed"),"Overdue","On Track")))))
M35: =IF(D35="","",IF(H35="Completed","Completed",IF(H35="Blocked","Blocked",IF(H35="Delayed","Delayed",IF(AND(G35<>"",G35<TODAY(),H35<>"Completed"),"Overdue","On Track")))))
M36: =IF(D36="","",IF(H36="Completed","Completed",IF(H36="Blocked","Blocked",IF(H36="Delayed","Delayed",IF(AND(G36<>"",G36<TODAY(),H36<>"Completed"),"Overdue","On Track")))))
M37: =IF(D37="","",IF(H37="Completed","Completed",IF(H37="Blocked","Blocked",IF(H37="Delayed","Delayed",IF(AND(G37<>"",G37<TODAY(),H37<>"Completed"),"Overdue","On Track")))))
M38: =IF(D38="","",IF(H38="Completed","Completed",IF(H38="Blocked","Blocked",IF(H38="Delayed","Delayed",IF(AND(G38<>"",G38<TODAY(),H38<>"Completed"),"Overdue","On Track")))))
M39: =IF(D39="","",IF(H39="Completed","Completed",IF(H39="Blocked","Blocked",IF(H39="Delayed","Delayed",IF(AND(G39<>"",G39<TODAY(),H39<>"Completed"),"Overdue","On Track")))))
M40: =IF(D40="","",IF(H40="Completed","Completed",IF(H40="Blocked","Blocked",IF(H40="Delayed","Delayed",IF(AND(G40<>"",G40<TODAY(),H40<>"Completed"),"Overdue","On Track")))))
...

Sheet Individual Contributions
A1: Individual Contribution Record
A2: Student Name | B2: Student Number | C2: Reporting Phase | D2: Activity | E2: Assigned Responsibility | F2: Work Personally Completed | G2: Date Completed | H2: Hours Spent | I2: Evidence / Link | J2: Verified by Group | K2: Verification Date | L2: Notes
A3: LP Moshoeu | B3: 223046876 | C3: Phase 2 | D3: Activity 3.3 | E3: Figma(Mobile Application) | F3: Do The figma mobile application | G3: 25/09/2026 | H3: 130 | I3: https://www.figma.com/proto/pG7mL3Oj2Rr37JAT9r7WJv/School-Parental-system?node-id=42-238&p=f&t=0WVSbhhXYOH6dG98-1&scaling=scale-down&content-scaling=fixed&page-id=0%3A1&starting-point-node-id=42%3A238 | J3: Yes | K3: 25/09/2026
A4: A Sithole | B4: 223000460 | C4: Phase 2 | D4: Activity 3.3 | E4: Figma(Web) | F4: To do the figma web | G4: 25/09/2026 | H4: 132 | I4: https://www.figma.com/proto/lPObV3qt8TfARP7lGBJZqU/School-Parental-System?node-id=197-2563&p=f&viewport=-167%2C288%2C0.1&t=Gi9OyypmECYmlsAf-1&scaling=contain&content-scaling=fixed&starting-point-node-id=197%3A2563&page-id=0%3A1 , https://www.figma.com/proto/lPObV3qt8TfARP7lGBJZqU/School-Parental-System?node-id=224-463&p=f&viewport=-107%2C84%2C0.19&t=7iRvLo52rvJGZx2o-1&scaling=contain&content-scaling=fixed&page-id=218%3A2&starting-point-node-id=281%3A2266 | J4: Yes | K4: 25/09/2026
A5: MA Nkuna | B5: 224000274 | C5: Phase 2 | D5: Activity 3.2 | E5: ERD | F5: To make our ERD | G5: 25/09/2026 | H5: 62 | J5: Yes | K5: 25/09/2026
A6: ST Pheko | B6: 223050336 | C6: Phase 2 | D6: Activity 3.1 | E6: System Architecture | F6: To make the system Archicture | G6: 25/09/2026 | H6: 60 | I6: https://viewer.diagrams.net/?tags=%7B%7D&lightbox=1&highlight=0000ff&edit=_blank&layers=1&nav=1&dark=auto#Uhttps%3A%2F%2Fdrive.google.com%2Fuc%3Fid%3D1ClYwvn3JjYWEF-mdmsHK64CJf6675N-G%26export%3Ddownload | J6: Yes | K6: 25/09/2026
A7: TMC Motone | B7: 224027806 | C7: Phase 2 | D7: Activity 3.2 | E7: Sequence Diagram | F7: To draw up our Sequence Diagram | G7: 25/09/2026 | H7: 55 | J7: Yes | K7: 25/09/2026
A8: PA Luthanda | B8: 222023335 | C8: Phase 2 | D8: Activity 3.2 | E8: Use Case Diagram | F8: To make our use case | G8: 25/09/2026 | H8: 53 | I8: https://viewer.diagrams.net/?tags=%7B%7D&lightbox=1&highlight=0000ff&edit=_blank&layers=1&nav=1&dark=auto#R%3Cmxfile%3E%3Cdiagram%20name%3D%22Page-1%22%20id%3D%22tkUWnzN3mPbntrwzPGwB%22%3E7V3bkqM4Ev2aehwHAsTlscrV07MR3bG9XRszu4%2BUUdvM2OAF1W2%2BfiVA2Eq7bCwrsd3lio4ZI4MwR0c6mamUuPHGi9fPZbKcfS1SNr9xnfT1xru%2FcV0SOp74nyx5a0uI4zQl0zJL27JVwUP2N2sL1WlPWcoq7UReFHOeLfXCSZHnbMK1sqQsixf9tB%2FFXL%2FrMpmyjYKHSTLfLP0jS%2FmsKY2osyr%2FjWXTGYfPt0jUyW1BNUvS4mWtyPt0443LouDNp8XrmM0legqX5rpf3%2Fm2%2B2Ely3mfC5Ln32c%2F%2FvVHOA0S8s9oufj%2Bd%2FXply21tEUVf1MYlMVTnjJZjXPj3b3MMs4elslEfvsiml2UzfhiLo6I%2BNhc%2FZzMn9qr2wJWcva6dof2R35mxYLx8k2cMlvHMQ5a2F5WqFMFZVuPp45bcvntYdK2%2BbSrewWL%2BNAicwBKbh%2BURPsu5cenxfx2wotSYCEfOhNc%2BpI8svm3osp4VuTilMeC82KxdsLtPJvKL3gB0PxR5LztFCTehu7D05KVoug2XWS5EdQx3QA60nEOdZhJjIUz7YOzqEd0fmbAxO9smlW8huthMhOjiBFe4SYxiQ%2BI6dGBEAtwEUvSVFbVguWkCU%2BwMKMxwIxiYRbiYiYkkHF2KthcDwu2qKmXpRuCuYlj8VRO2I666CbeeXor5VocFUsmxsI7UaJGPoHTXZpUs1qDiI6%2FLk7il5Rv%2F1k%2F%2BK88GFF1eP%2B6%2FuX9mzp6zXh92Sj2aXvcXOnVd5fHq0vlwfqV31iZCZDFyNKUNU%2FHk3LK%2BP7Oq2llkCwkwea8rmb96B%2F5ZP6USmJ15VPtrPZoG6lKNk949qw33Dqrgh2saav7VmSimTvi%2BZB4DqiiIUF71bpdAiqi4Z6KGhw3KqpJ3D2jOa%2BVpWmF2CEasRVBNXLS3dTsOsMo9vT%2BEO3rD%2FLIkNb0IFp%2FeuWsfs5z4XUY6nRUFuyhvA4caATQYXndy2o117nnjL3Ip6l%2FSaN1FZpB5etY%2BmjGAfFxUWNpxjXbgPEkwwMuoAA4NPOAUIvDqOLuWRoIQayNwcGeQdjcPlBcvFAD4acZSHs5WSdy%2F9U4Yu7%2FE3JoACDaRYbjAi1OH6htaRYXvSXnFbKHBoMBFG0I3jXi2tSuNdyQ1SsYDDrXonp1EV80L4Ac4AX0FBv1dBcqNhHRmOIFgR2x8YJhxcbtFQM9jdg0v8mst2%2BJMitkVSVOpMtMiBY1dXuFALFBdv1tIP%2BbJZOZjFEjgUx1kAnktzWQPW8QLR%2FPsnk6gBZBGQ9cLHZ6vkUtUq1gX4t66op3WDjo7HQFWCA%2B6C69dYXsqQhZVzzkubW2N05Ub0y4DOsl%2BUQ2ZZKn4r%2Bfy0RO5btjrC4KzcUAbULYQ55Duq3n3XgjBYNF1UKChlc8CPtWgOF6dBA3NENF3diOFMRYUmDilpgG4nrKjn%2Fh7gw0NkJD2XFBRcoeGEh2%2FGFCEquO3zZX%2Flgt6%2FPRQxQgNhaiaY4%2FkILPk6pitYRXlXBi6pk5Xgw1lhIHbzCNcAEclyypEz86CA0gi3pABly4CMbD7eVjIYdjPzW9t8ZrvauK245va%2Fbpot7YkQ%2Br%2BKPk5VFwb%2FGYu8Sjd6zKyI2w4LY5habY%2FiHUXjXZz6H2YWTqZILZ3jAEvwVZ7ekgZv6GxK98zapuoElRpltMAUujMd09GhMXgm4v2RPZ62wtAOWnCySXRcnRgAsAcD6ajgXIyt9Qbg26gajmRWhUQ%2B7Jrd0%2BRcUL2ubEQ7Mt1Z2sSHeALt0yi0VT7yBSam5Xv4%2FJjo0vWtNBemwEu2pvTYfmpw%2FMT2RND5E9%2BInympI8F1ydsIW8jRvUjVotk1y7UfC%2FJ7leqrnLL1Vzm1v580rWNHZ7gvikmv%2FG9ZrpzKClza9NtUHHiEHkjcZYfkOIbBf83mbN%2FOQNFKGpQ9QrdCOeTz5v0k4dT8Spcsxspozb02T7wDnmRZam8kvZGJMsn35hP%2BQ9vFXJ9xaYuoiXxV9sXMzlhPZ9XuSsVgme8OSxvoUcopdyNKlRoHfin%2FTH5VhP7%2BXsDb0jq2PxT55e8nGRi6qTrH4%2BllT8hVX85t25b7qNaF0227caqER%2BfHirOFtYsebdYIMUINGNutCBQmIE6ZfnYSsYJWt9evyTTQyzNwyiUjFabyIu8qq3r0n5l%2BZWGmHWJ%2FgJDXqC5juSfjkvFnS8JdyGl26z6GeXohCugbLIA2TPruMBe24a59ro7zQ69E5DtPgHwc7%2B%2BFJM5W%2FIrci0wayRhzduWp2CdzcxXzn2rS12YNzdA3%2B73Xhzd3xbGldvX%2FoAvxlIog9btn%2FC1Z6KsFeNqKnvMyDOkWueTkM4sjVzEIFy3e4M3UIlQ8rBUclVmZyDUc69Uu4oyrkDMQ7Ye67n2mGcB6mLzjjv%2FBg3cnxfZ50Xxqfh3THL6L1t8e9LIqPvDJviTHyb%2BROd%2FBxJRwKouIVSh%2B7DsJrFcTydsHuncY4YG7ftVnLWdAz0JWERzKFEp2Ngk447k3fPgo0aE62sSRyKc54f6zIKs2T7cg6SN3aGnawjfmhTj3euY%2B3rrh7CC0yenh3ngFqaJn0RGHiHqzjQOWdzZzBv5w5KV85Z5Vy39dbR49zgfkdsk3PHaevKGnP1nWFCQ4fhg5ARJqtSUzKCQHoMd4nAJiO1GSLenbd9HQCP5Jxu6EWUGHLu1IYetRld7rIRrqTDIB3kiuka8tOTzma0j9pS3djTeOcGezZsRfaFL4yNxIErFi%2BHjjY3ygiujgci6UJfJ10XnLs80tkMMqvk6ivprqTbSTqbYb0uBezKOhTWwQ224OIRY7%2BWDM06m4G98KqviKQDW%2BeRyNjHiGBkb2jS2YzsuQik20YfKzE%2BS2vhsfKmBGrJ29oJ7RqRdzkZOTqTvHZeYkWYpsaBsxIGT8oKbEZqPiKh1dzCifkcAz77jrOTeBFIQKXOQfx3wngU6wasKB0ZDut%2B5I%2Fi9T%2B9ZhpEIxgKRe8Xrs1%2BgRDAtNcvnFEsLHitbwR7M9KOMTvORQJAZq1PopF3UCeAKuAY7oPmx7v5H56A%2F1ZTJy9IF%2Byogn8eFO8mG5W9HB02ylsjONyoFk7to9PZZjD249G5W9R6aj6Dd6qq97D2tloAn4kpn2Hwjgyd1hTYTN%2F8eIRWfvypTRAYz%2FAP4zNcG%2BQZj8965gFx4fp4dD7bjOadt72NwWeVEnxqPgNCqtcQGPI5Mg2r%2BOGelGl0OluNE541neXrOwMQw0b0Hs9k5I430mYOYjoB4ZrIN2V6oFsiG28VwGa61b3lPp4honTv1HQG4cCYHjZwAzvGNd0RHg7cZOPl9Oh8vgbEj%2FUVw%2FOgNJygdvdExIHxQfz4VMZ4BH6IP%2FDawND9MH3AkdMYuvGydxeAI6yX8Dz6RvTOCpl3%2B4YP%2BgY9zLCH5o4LGd23b1AQACIhfNc2et%2BwGhg%2Fa8seRx%2BC8%2BwCxw73xr4qBX2DeMqkH4zSVoPjKBsT9H4But2ucGGjOngJJKGHJbU4cFdol4yC1Z%2FxkK1NbgbAuBl8PZyaesLbnzNPpkPubQr34I7RXvJEQquZvrsGCjv7yHtuqA0I9Oz2ke%2FoeJkbyUPxMl49trGRfDBwZifyxqPf2TSrJDvc9TfUN6%2BMOubN1QbbUW7M7fQYH8RhWcidSVeYi2eefS1SJs%2F4Pw%3D%3D%3C%2Fdiagram%3E%3C%2Fmxfile%3E | J8: Yes | K8: 25/09/2026
A10: LP Moshoeu | B10: 223046876 | C10: Phase 3 | D10: Sections 1 & 2 | E10: Flutter and supabase | F10: Developing some functions of flutter and making sure its connected to our supabase and it communicates with our ASP.NET application | G10: 25/10/2026 | H10: 90 | I10: Submitted our project | J10: Yes
A11: A Sithole | B11: 223000460 | C11: Phase 3 | D11: Sections 1 & 3 | E11: ASP.NET and supabase | F11: Developing some functions of our ASP.NET application and makiing sure it communicates with our supabase and that when they mark attendence what ever the case may be it interlinks withour flutter | G11: 25/10/2026 | H11: 150 | I11: Submitted our project | J11: Yes
A12: MA Nkuna | B12: 224000274 | C12: Phase 3 | D12: Sections 1 & 3 | E12: ASP.NET and supabase | F12: Developing some functions of our ASP.NET application and makiing sure it communicates with our supabase and that when they mark attendence what ever the case may be it interlinks withour flutter | G12: 25/10/2026 | H12: 150 | I12: Submitted our project | J12: Yes
A13: ST Pheko | B13: 223050336 | C13: Phase 3 | D13: Sections 1 & 2 | E13: Flutter and supabase | F13: Developing some functions of flutter and making sure its connected to our supabase and it communicates with our ASP.NET application | G13: 25/10/2026 | H13: 83 | I13: Submitted our project | J13: Yes
A14: TMC Motone | B14: 224027806 | C14: Phase 3 | D14: Sections 1 & 3 | E14: ASP.NET and supabase | F14: Developing some functions of our ASP.NET application and makiing sure it communicates with our supabase and that when they mark attendence what ever the case may be it interlinks withour flutter | G14: 25/10/2026 | H14: 79 | I14: Submitted our project | J14: Yes
A15: PA Luthanda | B15: 222023335 | C15: Phase 3 | D15: Sections 1 & 2 | E15: Flutter and supabase | F15: Developing some functions of flutter and making sure its connected to our supabase and it communicates with our ASP.NET application | G15: 25/10/2026 | H15: 81 | I15: Submitted our project | J15: Yes

Sheet Stakeholder Engagement
A1: Stakeholder Engagement Record
A2: Date | B2: Reporting Phase | C2: Type of Engagement | D2: Purpose | E2: Students Present | F2: Stakeholder Present / Role | G2: Main Findings | H2: Action Required | I2: Evidence / Link
B3: Unit 1 / Phase 1 | C3: Meeting | D3: Requirements-gathering interview for the School Portal System | E3: Group | F3: J.B Setlhare - Administrator, Reitzpark Primary School (since 2021) | G3: School currently has no dedicated app for parent communication; relies on printed circulars, class WhatsApp groups and Facebook; admin cannot confirm whether parents received/read notices. | H3: Incorporate communication read/acknowledgement tracking into SRS requirements | I3: Signed interview form, school-stamped (Reitzpark Primary School)
B4: Unit 1 / Phase 1 | C4: Meeting | D4: Requirements-gathering interview for the School Portal System | E4: Group | F4: Z. Horn - Educator, Thabong primary school (10 years) | G4: Many parents have no WhatsApp, Facebook, data or smartphones; notices sent via class WhatsApp groups and Facebook often go unanswered or use wrong contact numbers; teacher cannot confirm receipt. | H4: Confirm need for multi-channel and offline-friendly communication design; capture as a business rule in the SRS | I4: Signed interview form, school-stamped (Reitzpark Primary School)
B5: Unit 1 / Phase 1 | C5: Meeting | D5: Requirements-gathering interview for the School Portal System | E5: Group | F5: R.I Mocke - Remedial Education, Lenakeng High school (14 years) | G5: Parent meetings, phone calls and letters sent home with learners are current methods; letters often are not handed to parents and parents do not answer calls from the school; requested access to the system from phone/laptop. | H5: Include Parent Acknowledgement feature and multi-device (web/mobile) access in the SRS | I5: Signed interview form, school-stamped (Reitzpark Primary School)
B6: Phase 2 | C6: Site Visit | D6: We went to present our Figma mobile application prototype and Website prototype to get approval | E6: Group | F6: J.B Setlhare - Administrator, Reitzpark Primary School (since 2021) | G6: The teachers were worried that our mobile application might be just a bit difficult for some parents to navigate | H6: We promised teachers that we will make a short video tutorial on how to navigate the mobile application app so that we make it easier for parents to grasp how it works | I6: Signed interview form, school-stamped (Reitzpark Primary School)
B7: Phase 3 | C7: Site Visit | D7: We went to present our final project for both our ASP.NET application and flutter application and they where happy with our project | E7: Group | F7: MM Landman | G7: the school admin was concerned that the system might be tricky to se but they also said with time they will get used to the system | H7: We must make a video for the school so that they can find it more easier to use the system | I7: Signed interview form, school-stamped (Reitzpark Primary School)

Sheet Challenges & Actions
A1: Challenges and Corrective Actions
A2: Date Identified | B2: Reporting Phase | C2: Challenge | D2: Effect on Progress | E2: Corrective Action | F2: Responsible Student | G2: Target Date | H2: Status
B3: Unit 1 / Phase 1 | C3: Parents at Reitzpark Primary School often lack smartphones, data or social media accounts, limiting WhatsApp/Facebook-based communication. | D3: Adds complexity to designing an inclusive, multi-channel communication module. | E3: Documented multi-channel communication and notification requirements in SRS Sections 5.10 and 9.1-9.3. | F3: Group | H3: Resolved
B4: Unit 1 / Phase 1 | C4: The school has no reliable way to confirm parents received important notices (circulars, WhatsApp messages). | D4: Highlighted a core stakeholder problem that had to be reflected accurately in the requirements. | E4: Added Parent Acknowledgement and Read/Unread Tracking requirements (SRS Section 5.10.4-5.10.5). | F4: Group | H4: Resolved
B6: Phase 2 | C6: Some of the the teachers at the school didn’t like our design of our mobile application as they felt it might be complicated for some parents to use | D6: We had to redesign our mobile application prototype to try and make it easier for some parents to be able to navigate the mobile application | E6: Mobile design prototype was adjusted slightly as to make it esier for parents | F6: Group | G6: 25/09/2026 | H6: Resolved
B7: Phase 2 | C7: Coming up with ideas for our web and mobile figma prototypes | D7: It made us take longer to design as it required a lot of brainstrtorming and planning | E7: We made suggestions to what could be improved or adjusted as to make it more easier to to make the necessary changes and adjustments | F7: Group | G7: 20/09/2026 | H7: Resolved
B8: Phase 3 | C8: we found that most parents would like if they could also view their kids previous reports on the flutter mobile application | D8: We needed to re code our reports page so that the parents don’t just access their kids current reports but also their past reports | E8: We made the system to be able to show previous reports | F8: group | G8: 21/10/2026 | H8: Resolved

Sheet Phase Summary
A1: Phase Progress Summary
A3: Summary Information | B3: Group Response | D3: Phase Completion Checklist
A4: Reporting phase | B4: Phase 3 | D4: Initial or updated SRS completed | E4: Yes
A5: Reporting period | D5: Progress report updated | E5: Yes
A6: Overall phase status | B6: Completed | D6: Individual contributions recorded | E6: Yes
A7: What was completed during this phase? | B7: Completed our project build of flutter and ASP.NET | D7: Stakeholder engagement recorded | E7: Yes
A8: What remains incomplete? | B8: nothing | D8: Challenges and actions updated | E8: Yes
A9: Why is it incomplete? | B9: nothing | D9: Group reflection completed | E9: Yes
A10: Which contributions were particularly important? | B10: The stakeholder interviews with Reitzpark Primary School staff were particularly important, directly shaping the communication | D10: Microsoft Project updated | E10: Yes
A11: Were there participation concerns? | B11: yes | D11: GitHub evidence available | E11: Yes
A12: What will the group improve in the next phase? | D12: Confidential peer check completed | E12: Yes
A13: Main priority for the next phase

Sheet Group Reflection
A1: Group Reflection
A3: Reflection Information | B3: Group Response | D3: Reflection Guidance
A4: Reporting phase | B4: Phase 3 | D4: Length | E4: Approximately 300–400 words in total.
A5: Project title | B5: School Portal System (School-Parental System) - ITC327W | D5: Focus | E5: Discuss the group’s actual experience, not the activity instructions.
A6: Most important learning from this phase | B6: Being able to think outside the box and finding ways to be more creative and adapt according to what will make our stakeholders satisfied | D6: Honesty | E6: Identifying a genuine challenge will not disadvantage the group when an improvement action is provided.
A7: What went well and why? | B7: setting up supabase as we had a clear uml diagram that guided us in ensuring we have everything necessary | D7: Evidence | E7: Ensure that claims about participation agree with the contribution record, Microsoft Project and GitHub.
A8: What was difficult and why? | B8: Brainstorming and coming up with ideas to make our website more attractive and pleasing to the eye | D8: Research use | E8: Student work may only be used for research after the required ethical approval and consent processes.
A9: How were tasks divided among members? | B9: 3 Members of the group did ASP.NET while the other 3 dealt with ASP.net
A10: Did all members contribute fairly? Explain. | B10: yes as each person did the task they were given
A11: How did the group handle disagreements or delays? | B11: We would have a group meeting to discuss whatever disagreement we had at the time
A12: What did the group learn from the stakeholder? | B12: The group learned that Reitzpark Primary School relies heavily on WhatsApp, Facebook and printed circulars to reach parents, but has no reliable way to confirm a notice was received or read, and that many parents lack smartphones or data. This directly informed the Parent Acknowledgement and Read/Unread Tracking requirements in the SRS.
A13: Improvement action 1 for the next phase | B13: Communication should be on point and we must communicate more and work according to our planned schedule
A14: Improvement action 2 for the next phase
A15: Priority for the next phase
